Workbook

Sheet Sheet1
B1: splited_cmd | C1: obj名 | D1: gimmick名 | E1: 作用 | G1: splited_cmd | H1: obj名 | I1: gimmick名 | J1: 作用 | K1: split_cmd | L1: obj名 | M1: gimmick名 | N1: 作用 | O1: split_cmd | P1: obj名 | Q1: gimmick名 | R1: 作用 | S1: split_cmd | T1: obj名 | U1: gimmick名 | V1: 作用 | W1: split_cmd | X1: obj名 | Y1: gimmick名 | Z1: 作用 | AA1: split_cmd | AB1: obj名 | AC1: gimmick名 | AD1: 作用 | AE1: split_cmd | AF1: obj名 | AG1: gimmick名 | AH1: 作用 | AI1: split_cmd | AJ1: obj名 | AK1: gimmick名 | AL1: 作用 | AM1: split_cmd | AN1: obj名 | AO1: gimmick名 | AP1: 作用 | AQ1: split_cmd | AR1: obj名 | AS1: gimmick名 | AT1: 作用 | AU1: split_cmd | AV1: obj名 | AW1: gimmick名 | AX1: 作用 | AY1: split_cmd | AZ1: obj名 | BA1: gimmick名 | BB1: 作用 | BC1: split_cmd | BD1: obj名 | BE1: gimmick名 | BF1: 作用 | BG1: split_cmd | BH1: obj名 | BI1: gimmick名 | BJ1: 作用 | BK1: split_cmd | BL1: obj名 | BM1: gimmick名 | BN1: 作用 | BO1: split_cmd | BP1: obj名 | BQ1: gimmick名 | BR1: 作用 | BS1: split_cmd | BT1: obj名 | BU1: gimmick名 | BV1: 作用 | BW1: split_cmd | BX1: obj名 | BY1: gimmick名 | BZ1: 作用 | CA1: split_cmd | CB1: obj名 | CC1: gimmick名 | CD1: 作用 | CE1: split_cmd | CF1: obj名 | CG1: gimmick名 | CH1: 作用 | CI1: split_cmd | CJ1: obj名 | CK1: gimmick名 | CL1: 作用 | CM1: split_cmd | CN1: obj名 | CO1: gimmick名 | CP1: 作用 | CQ1: split_cmd | CR1: obj名 | CS1: gimmick名 | CT1: 作用
B2: {=_xlfn.TEXTSPLIT(Sheet2!B2,," ")} -> addExtraMod("glitchamp"); | C2: =Sheet2!A2 -> obj___gimmick | D2: =MID(B2,14,FIND(")",B2,14)-14-1) -> glitchamp | G2: {=_xlfn.TEXTSPLIT(Sheet2!B4,," ")} -> addExtraMod("glitchamp"); | H2: =Sheet2!A4 -> obj_aleph_gimmick | I2: =MID(G2,14,FIND(")",G2,14)-14-1) -> glitchamp | K2: {=_xlfn.TEXTSPLIT(Sheet2!B5,," ")} -> addExtraMod("uialpha"); | L2: =Sheet2!A5 -> obj_angelstar_gimmick | M2: =MID(K2,14,FIND(")",K2,14)-14-1) -> uialpha | O2: {=_xlfn.TEXTSPLIT(Sheet2!B$6,," ")} -> addExtraMod("gray"); | P2: =Sheet2!A$6 -> obj_astellion_gimmick | Q2: =MID(O2,14,FIND(")",O2,14)-14-1) -> gray | S2: {=_xlfn.TEXTSPLIT(Sheet2!$B7,," ")} -> addExtraMod("glitchamp"); | T2: =Sheet2!$A7 -> obj_convergence_gimmick | U2: =MID(S2,14,FIND(")",S2,14)-14-1) -> glitchamp | W2: {=_xlfn.TEXTSPLIT(Sheet2!$B8,," ")} -> addExtraMod("df_sideline"); | X2: =Sheet2!$A8 -> obj_distortedfate_gimmick | Y2: =MID(W2,14,FIND(")",W2,14)-14-1) -> df_sideline | AA2: {=_xlfn.TEXTSPLIT(Sheet2!$B9,," ")} -> addExtraMod("cover1"); | AB2: =Sheet2!$A9 -> obj_dracula_gimmick | AC2: =MID(AA2,14,FIND(")",AA2,14)-14-1) -> cover1 | AE2: {=_xlfn.TEXTSPLIT(Sheet2!$B10,," ")} -> addExtraMod("df_sideline"); | AF2: =Sheet2!$A10 -> obj_firstbreath_gimmick | AG2: =MID(AE2,14,FIND(")",AE2,14)-14-1) -> df_sideline | AI2: {=_xlfn.TEXTSPLIT(Sheet2!$B11,," ")} -> addExtraMod("uialpha"); | AJ2: =Sheet2!$A11 -> obj_lastwish_gimmick | AK2: =MID(AI2,14,FIND(")",AI2,14)-14-1) -> uialpha | AM2: {=_xlfn.TEXTSPLIT(Sheet2!$B12,," ")} -> addExtraMod("glitchamp"); | AN2: =Sheet2!$A12 -> obj_libertia_gimmick | AO2: =MID(AM2,14,FIND(")",AM2,14)-14-1) -> glitchamp | AQ2: {=_xlfn.TEXTSPLIT(Sheet2!$B13,," ")} -> addExtraMod("glitchamp"); | AR2: =Sheet2!$A13 -> obj_marenol_gimmick | AS2: =MID(AQ2,14,FIND(")",AQ2,14)-14-1) -> glitchamp | AU2: {=_xlfn.TEXTSPLIT(Sheet2!$B14,," ")} -> addExtraMod("glitchamp"); | AV2: =Sheet2!$A14 -> obj_memories_gimmick | AW2: =MID(AU2,14,FIND(")",AU2,14)-14-1) -> glitchamp | AY2: {=_xlfn.TEXTSPLIT(Sheet2!$B15,," ")} -> addExtraMod("glitchamp"); | AZ2: =Sheet2!$A15 -> obj_multigrode_gimmick | BA2: =MID(AY2,14,FIND(")",AY2,14)-14-1) -> glitchamp | BC2: {=_xlfn.TEXTSPLIT(Sheet2!$B16,," ")} -> addExtraMod("c_flash"); | BD2: =Sheet2!$A16 -> obj_pictured_gimmick | BE2: =MID(BC2,14,FIND(")",BC2,14)-14-1) -> c_flash | BG2: {=_xlfn.TEXTSPLIT(Sheet2!$B17,," ")} -> addExtraMod("glitchamp"); | BH2: =Sheet2!$A17 -> obj_plaudite_gimmick | BI2: =MID(BG2,14,FIND(")",BG2,14)-14-1) -> glitchamp | BK2: {=_xlfn.TEXTSPLIT(Sheet2!$B18,," ")} -> addExtraMod("glitchamp"); | BL2: =Sheet2!$A18 -> obj_ram_gimmick | BM2: =MID(BK2,14,FIND(")",BK2,14)-14-1) -> glitchamp | BO2: {=_xlfn.TEXTSPLIT(Sheet2!$B19,," ")} -> addExtraMod("uialpha"); | BP2: =Sheet2!$A19 -> obj_scarletdeath_gimmick | BQ2: =MID(BO2,14,FIND(")",BO2,14)-14-1) -> uialpha | BS2: {=_xlfn.TEXTSPLIT(Sheet2!$B20,," ")} -> addExtraMod("glitchamp"); | BT2: =Sheet2!$A20 -> obj_self_gimmick | BU2: =MID(BS2,14,FIND(")",BS2,14)-14-1) -> glitchamp | BW2: {=_xlfn.TEXTSPLIT(Sheet2!$B21,," ")} -> addExtraMod("gray"); | BX2: =Sheet2!$A21 -> obj_stargazers_gimmick | BY2: =MID(BW2,14,FIND(")",BW2,14)-14-1) -> gray | CA2: {=_xlfn.TEXTSPLIT(Sheet2!$B22,," ")} -> addExtraMod("glitchamp"); | CB2: =Sheet2!$A22 -> obj_stopmotion_gimmick | CC2: =MID(CA2,14,FIND(")",CA2,14)-14-1) -> glitchamp | CE2: {=_xlfn.TEXTSPLIT(Sheet2!$B23,," ")} -> addExtraMod("glitchamp"); | CF2: =Sheet2!$A23 -> obj_supernova_gimmick | CG2: =MID(CE2,14,FIND(")",CE2,14)-14-1) -> glitchamp | CI2: {=_xlfn.TEXTSPLIT(Sheet2!$B24,," ")} -> addExtraMod("glitchamp"); | CJ2: =Sheet2!$A24 -> obj_times_gimmick | CK2: =MID(CI2,14,FIND(")",CI2,14)-14-1) -> glitchamp | CM2: {=_xlfn.TEXTSPLIT(Sheet2!$B25,," ")} -> addExtraMod("glitchamp"); | CN2: =Sheet2!$A25 -> obj_tutorial_gimmick | CO2: =MID(CM2,14,FIND(")",CM2,14)-14-1) -> glitchamp | CQ2: {=_xlfn.TEXTSPLIT(Sheet2!$B26,," ")} -> addExtraMod("gray"); | CR2: =Sheet2!$A26 -> obj_unraveling_gimmick | CS2: =MID(CQ2,14,FIND(")",CQ2,14)-14-1) -> gray
B3: addExtraMod("glitchoffset"); | D3: =MID(B3,14,FIND(")",B3,14)-14-1) -> glitchoffset | G3: addExtraMod("uialpha"); | I3: =MID(G3,14,FIND(")",G3,14)-14-1) -> uialpha | K3: addExtraMod("cover1"); | M3: =MID(K3,14,FIND(")",K3,14)-14-1) -> cover1 | O3: addExtraMod("barrel"); | Q3: =MID(O3,14,FIND(")",O3,14)-14-1) -> barrel | S3: addExtraMod("uialpha"); | U3: =MID(S3,14,FIND(")",S3,14)-14-1) -> uialpha | W3: addExtraMod("df_whitebg"); | Y3: =MID(W3,14,FIND(")",W3,14)-14-1) -> df_whitebg | AA3: addExtraMod("cover2"); | AC3: =MID(AA3,14,FIND(")",AA3,14)-14-1) -> cover2 | AE3: addExtraMod("df_whitebg"); | AG3: =MID(AE3,14,FIND(")",AE3,14)-14-1) -> df_whitebg | AI3: addExtraMod("bgalph"); | AK3: =MID(AI3,14,FIND(")",AI3,14)-14-1) -> bgalph | AM3: addExtraMod("uialpha"); | AO3: =MID(AM3,14,FIND(")",AM3,14)-14-1) -> uialpha | AQ3: addExtraMod("glitchoffset"); | AS3: =MID(AQ3,14,FIND(")",AQ3,14)-14-1) -> glitchoffset | AU3: addExtraMod("uialpha"); | AW3: =MID(AU3,14,FIND(")",AU3,14)-14-1) -> uialpha | AY3: addExtraMod("uialpha"); | BA3: =MID(AY3,14,FIND(")",AY3,14)-14-1) -> uialpha | BC3: addExtraMod("c_shader"); | BE3: =MID(BC3,14,FIND(")",BC3,14)-14-1) -> c_shader | BG3: addExtraMod("uialpha"); | BI3: =MID(BG3,14,FIND(")",BG3,14)-14-1) -> uialpha | BK3: addExtraMod("glitchoffset"); | BM3: =MID(BK3,14,FIND(")",BK3,14)-14-1) -> glitchoffset | BO3: addExtraMod("cover1"); | BQ3: =MID(BO3,14,FIND(")",BO3,14)-14-1) -> cover1 | BS3: addExtraMod("uialpha"); | BU3: =MID(BS3,14,FIND(")",BS3,14)-14-1) -> uialpha | BW3: addExtraMod("barrel"); | BY3: =MID(BW3,14,FIND(")",BW3,14)-14-1) -> barrel | CA3: addExtraMod("uialpha"); | CC3: =MID(CA3,14,FIND(")",CA3,14)-14-1) -> uialpha | CE3: addExtraMod("uialpha"); | CG3: =MID(CE3,14,FIND(")",CE3,14)-14-1) -> uialpha | CI3: addExtraMod("static"); | CK3: =MID(CI3,14,FIND(")",CI3,14)-14-1) -> static | CM3: addExtraMod("uialpha"); | CO3: =MID(CM3,14,FIND(")",CM3,14)-14-1) -> uialpha | CQ3: addExtraMod("barrel"); | CS3: =MID(CQ3,14,FIND(")",CQ3,14)-14-1) -> barrel
B4: addExtraMod("fish"); | D4: =MID(B4,14,FIND(")",B4,14)-14-1) -> fish | G4: addExtraMod("scorealph"); | I4: =MID(G4,14,FIND(")",G4,14)-14-1) -> scorealph | K4: addExtraMod("cover2"); | M4: =MID(K4,14,FIND(")",K4,14)-14-1) -> cover2 | O4: addExtraMod("barrel2"); | Q4: =MID(O4,14,FIND(")",O4,14)-14-1) -> barrel2 | S4: addExtraMod("scorealph"); | U4: =MID(S4,14,FIND(")",S4,14)-14-1) -> scorealph | W4: addExtraMod("df_grid_alpha"); | Y4: =MID(W4,14,FIND(")",W4,14)-14-1) -> df_grid_alpha | AA4: addExtraMod("cover3"); | AC4: =MID(AA4,14,FIND(")",AA4,14)-14-1) -> cover3 | AE4: addExtraMod("df_grid_alpha"); | AG4: =MID(AE4,14,FIND(")",AE4,14)-14-1) -> df_grid_alpha | AI4: addExtraMod("film"); | AK4: =MID(AI4,14,FIND(")",AI4,14)-14-1) -> film | AM4: addExtraMod("scorealph"); | AO4: =MID(AM4,14,FIND(")",AM4,14)-14-1) -> scorealph | AQ4: addExtraMod("fish"); | AS4: =MID(AQ4,14,FIND(")",AQ4,14)-14-1) -> fish | AU4: addExtraMod("scorealph"); | AW4: =MID(AU4,14,FIND(")",AU4,14)-14-1) -> scorealph | AY4: addExtraMod("scorealph"); | BA4: =MID(AY4,14,FIND(")",AY4,14)-14-1) -> scorealph | BC4: addExtraMod("uialpha"); | BE4: =MID(BC4,14,FIND(")",BC4,14)-14-1) -> uialpha | BG4: addExtraMod("scorealph"); | BI4: =MID(BG4,14,FIND(")",BG4,14)-14-1) -> scorealph | BK4: addExtraMod("fish"); | BM4: =MID(BK4,14,FIND(")",BK4,14)-14-1) -> fish | BO4: addExtraMod("cover2"); | BQ4: =MID(BO4,14,FIND(")",BO4,14)-14-1) -> cover2 | BS4: addExtraMod("scorealph"); | BU4: =MID(BS4,14,FIND(")",BS4,14)-14-1) -> scorealph | BW4: addExtraMod("barrel2"); | BY4: =MID(BW4,14,FIND(")",BW4,14)-14-1) -> barrel2 | CA4: addExtraMod("scorealph"); | CC4: =MID(CA4,14,FIND(")",CA4,14)-14-1) -> scorealph | CE4: addExtraMod("scorealph"); | CG4: =MID(CE4,14,FIND(")",CE4,14)-14-1) -> scorealph | CI4: addExtraMod("wflash"); | CK4: =MID(CI4,14,FIND(")",CI4,14)-14-1) -> wflash | CM4: addExtraMod("cover1"); | CO4: =MID(CM4,14,FIND(")",CM4,14)-14-1) -> cover1 | CQ4: addExtraMod("barrel2"); | CS4: =MID(CQ4,14,FIND(")",CQ4,14)-14-1) -> barrel2
B5: addExtraMod("vig"); | D5: =MID(B5,14,FIND(")",B5,14)-14-1) -> vig | G5: addExtraMod("bgalph"); | I5: =MID(G5,14,FIND(")",G5,14)-14-1) -> bgalph | K5: addExtraMod("cover3"); | M5: =MID(K5,14,FIND(")",K5,14)-14-1) -> cover3 | O5: addExtraMod("hdistort"); | Q5: =MID(O5,14,FIND(")",O5,14)-14-1) -> hdistort | S5: addExtraMod("bgalph"); | U5: =MID(S5,14,FIND(")",S5,14)-14-1) -> bgalph | W5: addExtraMod("df_grid_top"); | Y5: =MID(W5,14,FIND(")",W5,14)-14-1) -> df_grid_top | AA5: addExtraMod("uialpha"); | AC5: =MID(AA5,14,FIND(")",AA5,14)-14-1) -> uialpha | AE5: addExtraMod("df_grid_top"); | AG5: =MID(AE5,14,FIND(")",AE5,14)-14-1) -> df_grid_top | AI5: addExtraMod("glow"); | AK5: =MID(AI5,14,FIND(")",AI5,14)-14-1) -> glow | AM5: addExtraMod("bgalph"); | AO5: =MID(AM5,14,FIND(")",AM5,14)-14-1) -> bgalph | AQ5: addExtraMod("posx"); | AS5: =MID(AQ5,14,FIND(")",AQ5,14)-14-1) -> posx | AU5: addExtraMod("bgalph"); | AW5: =MID(AU5,14,FIND(")",AU5,14)-14-1) -> bgalph | AY5: addExtraMod("bgalph"); | BA5: =MID(AY5,14,FIND(")",AY5,14)-14-1) -> bgalph | BC5: addExtraMod("scorealph"); | BE5: =MID(BC5,14,FIND(")",BC5,14)-14-1) -> scorealph | BG5: addExtraMod("bgalph"); | BI5: =MID(BG5,14,FIND(")",BG5,14)-14-1) -> bgalph | BK5: addExtraMod("vig"); | BM5: =MID(BK5,14,FIND(")",BK5,14)-14-1) -> vig | BO5: addExtraMod("cover3"); | BQ5: =MID(BO5,14,FIND(")",BO5,14)-14-1) -> cover3 | BS5: addExtraMod("holdoverlayalpha"); | BU5: =MID(BS5,14,FIND(")",BS5,14)-14-1) -> holdoverlayalpha | BW5: addExtraMod("hdistort"); | BY5: =MID(BW5,14,FIND(")",BW5,14)-14-1) -> hdistort | CA5: addExtraMod("holdoverlayalpha"); | CC5: =MID(CA5,14,FIND(")",CA5,14)-14-1) -> holdoverlayalpha | CE5: addExtraMod("bgalph"); | CG5: =MID(CE5,14,FIND(")",CE5,14)-14-1) -> bgalph | CI5: addExtraMod("tx"); | CK5: =MID(CI5,14,FIND(")",CI5,14)-14-1) -> tx | CM5: addExtraMod("scorealph"); | CO5: =MID(CM5,14,FIND(")",CM5,14)-14-1) -> scorealph | CQ5: addExtraMod("hdistort"); | CS5: =MID(CQ5,14,FIND(")",CQ5,14)-14-1) -> hdistort
B6: addExtraMod("bloom"); | D6: =MID(B6,14,FIND(")",B6,14)-14-1) -> bloom | G6: addExtraMod("noteoverlayalp"); | I6: =MID(G6,14,FIND(")",G6,14)-14-1) -> noteoverlayalp | K6: addExtraMod("wflash"); | M6: =MID(K6,14,FIND(")",K6,14)-14-1) -> wflash | O6: addExtraMod("fish"); | Q6: =MID(O6,14,FIND(")",O6,14)-14-1) -> fish | S6: addExtraMod("noteoverlayalp"); | U6: =MID(S6,14,FIND(")",S6,14)-14-1) -> noteoverlayalp | W6: addExtraMod("df_grid_bottom"); | Y6: =MID(W6,14,FIND(")",W6,14)-14-1) -> df_grid_bottom | AA6: addExtraMod("vib"); | AC6: =MID(AA6,14,FIND(")",AA6,14)-14-1) -> vib | AE6: addExtraMod("df_grid_bottom"); | AG6: =MID(AE6,14,FIND(")",AE6,14)-14-1) -> df_grid_bottom | AI6: addExtraMod("filmsat"); | AK6: =MID(AI6,14,FIND(")",AI6,14)-14-1) -> filmsat | AM6: addExtraMod("noteoverlayalp"); | AO6: =MID(AM6,14,FIND(")",AM6,14)-14-1) -> noteoverlayalp | AQ6: addExtraMod("posy"); | AS6: =MID(AQ6,14,FIND(")",AQ6,14)-14-1) -> posy | AU6: addExtraMod("noteoverlayalp"); | AW6: =MID(AU6,14,FIND(")",AU6,14)-14-1) -> noteoverlayalp | AY6: addExtraMod("noteoverlayalp"); | BA6: =MID(AY6,14,FIND(")",AY6,14)-14-1) -> noteoverlayalp | BC6: addExtraMod("bgalph"); | BE6: =MID(BC6,14,FIND(")",BC6,14)-14-1) -> bgalph | BG6: addExtraMod("noteoverlayalp"); | BI6: =MID(BG6,14,FIND(")",BG6,14)-14-1) -> noteoverlayalp | BK6: addExtraMod("bloom"); | BM6: =MID(BK6,14,FIND(")",BK6,14)-14-1) -> bloom | BO6: addExtraMod("wflash"); | BQ6: =MID(BO6,14,FIND(")",BO6,14)-14-1) -> wflash | BS6: addExtraMod("bgalph"); | BU6: =MID(BS6,14,FIND(")",BS6,14)-14-1) -> bgalph | BW6: addExtraMod("fish"); | BY6: =MID(BW6,14,FIND(")",BW6,14)-14-1) -> fish | CA6: addExtraMod("bgalph"); | CC6: =MID(CA6,14,FIND(")",CA6,14)-14-1) -> bgalph | CE6: addExtraMod("noteoverlayalp"); | CG6: =MID(CE6,14,FIND(")",CE6,14)-14-1) -> noteoverlayalp | CI6: addExtraMod("tx2"); | CK6: =MID(CI6,14,FIND(")",CI6,14)-14-1) -> tx2 | CM6: addExtraMod("bgalph"); | CO6: =MID(CM6,14,FIND(")",CM6,14)-14-1) -> bgalph | CQ6: addExtraMod("fish"); | CS6: =MID(CQ6,14,FIND(")",CQ6,14)-14-1) -> fish
B7: addExtraMod("gray"); | D7: =MID(B7,14,FIND(")",B7,14)-14-1) -> gray | G7: addExtraMod("sg_endblip"); | I7: =MID(G7,14,FIND(")",G7,14)-14-1) -> sg_endblip | K7: addExtraMod("rainbow"); | M7: =MID(K7,14,FIND(")",K7,14)-14-1) -> rainbow | O7: addExtraMod("vig"); | Q7: =MID(O7,14,FIND(")",O7,14)-14-1) -> vig | S7: addExtraMod("sg_endblip"); | U7: =MID(S7,14,FIND(")",S7,14)-14-1) -> sg_endblip | W7: addExtraMod("df_sideline2"); | Y7: =MID(W7,14,FIND(")",W7,14)-14-1) -> df_sideline2 | AA7: addExtraMod("jart"); | AC7: =MID(AA7,14,FIND(")",AA7,14)-14-1) -> jart | AE7: addExtraMod("df_sideline2"); | AG7: =MID(AE7,14,FIND(")",AE7,14)-14-1) -> df_sideline2 | AI7: addExtraMod("lwcover"); | AK7: =MID(AI7,14,FIND(")",AI7,14)-14-1) -> lwcover | AM7: addExtraMod("sg_endblip"); | AO7: =MID(AM7,14,FIND(")",AM7,14)-14-1) -> sg_endblip | AQ7: addExtraMod("cover1"); | AS7: =MID(AQ7,14,FIND(")",AQ7,14)-14-1) -> cover1 | AU7: addExtraMod("sg_endblip"); | AW7: =MID(AU7,14,FIND(")",AU7,14)-14-1) -> sg_endblip | AY7: addExtraMod("sg_endblip"); | BA7: =MID(AY7,14,FIND(")",AY7,14)-14-1) -> sg_endblip | BC7: addExtraMod("noteoverlayalp"); | BE7: =MID(BC7,14,FIND(")",BC7,14)-14-1) -> noteoverlayalp | BG7: addExtraMod("sg_endblip"); | BI7: =MID(BG7,14,FIND(")",BG7,14)-14-1) -> sg_endblip | BK7: addExtraMod("gray"); | BM7: =MID(BK7,14,FIND(")",BK7,14)-14-1) -> gray | BO7: addExtraMod("rainbow"); | BQ7: =MID(BO7,14,FIND(")",BO7,14)-14-1) -> rainbow | BS7: addExtraMod("noteoverlayalp"); | BU7: =MID(BS7,14,FIND(")",BS7,14)-14-1) -> noteoverlayalp | BW7: addExtraMod("vig"); | BY7: =MID(BW7,14,FIND(")",BW7,14)-14-1) -> vig | CA7: addExtraMod("noteoverlayalp"); | CC7: =MID(CA7,14,FIND(")",CA7,14)-14-1) -> noteoverlayalp | CE7: addExtraMod("sg_endblip"); | CG7: =MID(CE7,14,FIND(")",CE7,14)-14-1) -> sg_endblip | CI7: addExtraMod("tx3"); | CK7: =MID(CI7,14,FIND(")",CI7,14)-14-1) -> tx3 | CM7: addExtraMod("noteoverlayalp"); | CO7: =MID(CM7,14,FIND(")",CM7,14)-14-1) -> noteoverlayalp | CQ7: addExtraMod("vig"); | CS7: =MID(CQ7,14,FIND(")",CQ7,14)-14-1) -> vig
B8: addExtraMod("posx"); | D8: =MID(B8,14,FIND(")",B8,14)-14-1) -> posx | G8: addExtraMod("glitchoffset"); | I8: =MID(G8,14,FIND(")",G8,14)-14-1) -> glitchoffset | K8: addExtraMod("sides"); | M8: =MID(K8,14,FIND(")",K8,14)-14-1) -> sides | O8: addExtraMod("abx"); | Q8: =MID(O8,14,FIND(")",O8,14)-14-1) -> abx | S8: addExtraMod("supernova_dialogue"); | U8: =MID(S8,14,FIND(")",S8,14)-14-1) -> supernova_dialogue | W8: addExtraMod("gray"); | Y8: =MID(W8,14,FIND(")",W8,14)-14-1) -> gray | AA8: addExtraMod("jdesat"); | AC8: =MID(AA8,14,FIND(")",AA8,14)-14-1) -> jdesat | AE8: addExtraMod("gray"); | AG8: =MID(AE8,14,FIND(")",AE8,14)-14-1) -> gray | AI8: addExtraMod("lwflickerspd"); | AK8: =MID(AI8,14,FIND(")",AI8,14)-14-1) -> lwflickerspd | AM8: addExtraMod("supernova_dialogue"); | AO8: =MID(AM8,14,FIND(")",AM8,14)-14-1) -> supernova_dialogue | AQ8: addExtraMod("cover2"); | AS8: =MID(AQ8,14,FIND(")",AQ8,14)-14-1) -> cover2 | AU8: addExtraMod("supernova_dialogue"); | AW8: =MID(AU8,14,FIND(")",AU8,14)-14-1) -> supernova_dialogue | AY8: addExtraMod("glitchoffset"); | BA8: =MID(AY8,14,FIND(")",AY8,14)-14-1) -> glitchoffset | BC8: addExtraMod("holdoverlayalpha"); | BE8: =MID(BC8,14,FIND(")",BC8,14)-14-1) -> holdoverlayalpha | BG8: addExtraMod("supernova_dialogue"); | BI8: =MID(BG8,14,FIND(")",BG8,14)-14-1) -> supernova_dialogue | BK8: addExtraMod("posx"); | BM8: =MID(BK8,14,FIND(")",BK8,14)-14-1) -> posx | BO8: addExtraMod("sides"); | BQ8: =MID(BO8,14,FIND(")",BO8,14)-14-1) -> sides | BS8: addExtraMod("sg_endblip"); | BU8: =MID(BS8,14,FIND(")",BS8,14)-14-1) -> sg_endblip | BW8: addExtraMod("abx"); | BY8: =MID(BW8,14,FIND(")",BW8,14)-14-1) -> abx | CA8: addExtraMod("sg_endblip"); | CC8: =MID(CA8,14,FIND(")",CA8,14)-14-1) -> sg_endblip | CE8: addExtraMod("supernova_dialogue"); | CG8: =MID(CE8,14,FIND(")",CE8,14)-14-1) -> supernova_dialogue | CI8: addExtraMod("txj"); | CK8: =MID(CI8,14,FIND(")",CI8,14)-14-1) -> txj | CM8: addExtraMod("sg_endblip"); | CO8: =MID(CM8,14,FIND(")",CM8,14)-14-1) -> sg_endblip | CQ8: addExtraMod("abx"); | CS8: =MID(CQ8,14,FIND(")",CQ8,14)-14-1) -> abx
B9: addExtraMod("posy"); | D9: =MID(B9,14,FIND(")",B9,14)-14-1) -> posy | G9: addExtraMod("uhnoise"); | I9: =MID(G9,14,FIND(")",G9,14)-14-1) -> uhnoise | K9: addExtraMod("notealp"); | M9: =MID(K9,14,FIND(")",K9,14)-14-1) -> notealp | O9: addExtraMod("aby"); | Q9: =MID(O9,14,FIND(")",O9,14)-14-1) -> aby | S9: addExtraMod("supernova_cg_xscale"); | U9: =MID(S9,14,FIND(")",S9,14)-14-1) -> supernova_cg_xscale | W9: addExtraMod("barrel"); | Y9: =MID(W9,14,FIND(")",W9,14)-14-1) -> barrel | AA9: addExtraMod("seedspeed"); | AC9: =MID(AA9,14,FIND(")",AA9,14)-14-1) -> seedspeed | AE9: addExtraMod("barrel"); | AG9: =MID(AE9,14,FIND(")",AE9,14)-14-1) -> barrel | AI9: addExtraMod("lwjitterintensity"); | AK9: =MID(AI9,14,FIND(")",AI9,14)-14-1) -> lwjitterintensity | AM9: addExtraMod("supernova_cg_xscale"); | AO9: =MID(AM9,14,FIND(")",AM9,14)-14-1) -> supernova_cg_xscale | AQ9: addExtraMod("cover3"); | AS9: =MID(AQ9,14,FIND(")",AQ9,14)-14-1) -> cover3 | AU9: addExtraMod("supernova_cg_xscale"); | AW9: =MID(AU9,14,FIND(")",AU9,14)-14-1) -> supernova_cg_xscale | AY9: addExtraMod("uhnoise"); | BA9: =MID(AY9,14,FIND(")",AY9,14)-14-1) -> uhnoise | BC9: addExtraMod("1_pinkbg_vis"); | BE9: =MID(BC9,14,FIND(")",BC9,14)-14-1) -> 1_pinkbg_vis | BG9: addExtraMod("supernova_cg_xscale"); | BI9: =MID(BG9,14,FIND(")",BG9,14)-14-1) -> supernova_cg_xscale | BK9: addExtraMod("posy"); | BM9: =MID(BK9,14,FIND(")",BK9,14)-14-1) -> posy | BO9: addExtraMod("notealp"); | BQ9: =MID(BO9,14,FIND(")",BO9,14)-14-1) -> notealp | BS9: addExtraMod("glitchoffset"); | BU9: =MID(BS9,14,FIND(")",BS9,14)-14-1) -> glitchoffset | BW9: addExtraMod("aby"); | BY9: =MID(BW9,14,FIND(")",BW9,14)-14-1) -> aby | CA9: addExtraMod("glitchoffset"); | CC9: =MID(CA9,14,FIND(")",CA9,14)-14-1) -> glitchoffset | CE9: addExtraMod("supernova_cg_xscale"); | CG9: =MID(CE9,14,FIND(")",CE9,14)-14-1) -> supernova_cg_xscale | CI9: addExtraMod("ty"); | CK9: =MID(CI9,14,FIND(")",CI9,14)-14-1) -> ty | CM9: addExtraMod("glitchoffset"); | CO9: =MID(CM9,14,FIND(")",CM9,14)-14-1) -> glitchoffset | CQ9: addExtraMod("aby"); | CS9: =MID(CQ9,14,FIND(")",CQ9,14)-14-1) -> aby
B10: addExtraMod("cover1"); | D10: =MID(B10,14,FIND(")",B10,14)-14-1) -> cover1 | G10: addExtraMod("abberationxamp"); | I10: =MID(G10,14,FIND(")",G10,14)-14-1) -> abberationxamp | K10: addExtraMod("video"); | M10: =MID(K10,14,FIND(")",K10,14)-14-1) -> video | O10: addExtraMod("aberamp"); | Q10: =MID(O10,14,FIND(")",O10,14)-14-1) -> aberamp | S10: addExtraMod("supernova_cg_alpha"); | U10: =MID(S10,14,FIND(")",S10,14)-14-1) -> supernova_cg_alpha | W10: addExtraMod("barrel2"); | Y10: =MID(W10,14,FIND(")",W10,14)-14-1) -> barrel2 | AA10: addExtraMod("wflash"); | AC10: =MID(AA10,14,FIND(")",AA10,14)-14-1) -> wflash | AE10: addExtraMod("barrel2"); | AG10: =MID(AE10,14,FIND(")",AE10,14)-14-1) -> barrel2 | AI10: addExtraMod("lwchroma"); | AK10: =MID(AI10,14,FIND(")",AI10,14)-14-1) -> lwchroma | AM10: addExtraMod("supernova_cg_alpha"); | AO10: =MID(AM10,14,FIND(")",AM10,14)-14-1) -> supernova_cg_alpha | AQ10: addExtraMod("sina"); | AS10: =MID(AQ10,14,FIND(")",AQ10,14)-14-1) -> sina | AU10: addExtraMod("supernova_cg_alpha"); | AW10: =MID(AU10,14,FIND(")",AU10,14)-14-1) -> supernova_cg_alpha | AY10: addExtraMod("abberationxamp"); | BA10: =MID(AY10,14,FIND(")",AY10,14)-14-1) -> abberationxamp | BC10: addExtraMod("1_speech"); | BE10: =MID(BC10,14,FIND(")",BC10,14)-14-1) -> 1_speech | BG10: addExtraMod("supernova_cg_alpha"); | BI10: =MID(BG10,14,FIND(")",BG10,14)-14-1) -> supernova_cg_alpha | BK10: addExtraMod("cover1"); | BM10: =MID(BK10,14,FIND(")",BK10,14)-14-1) -> cover1 | BO10: addExtraMod("video"); | BQ10: =MID(BO10,14,FIND(")",BO10,14)-14-1) -> video | BS10: addExtraMod("uhnoise"); | BU10: =MID(BS10,14,FIND(")",BS10,14)-14-1) -> uhnoise | BW10: addExtraMod("aberamp"); | BY10: =MID(BW10,14,FIND(")",BW10,14)-14-1) -> aberamp | CA10: addExtraMod("uhnoise"); | CC10: =MID(CA10,14,FIND(")",CA10,14)-14-1) -> uhnoise | CE10: addExtraMod("supernova_cg_alpha"); | CG10: =MID(CE10,14,FIND(")",CE10,14)-14-1) -> supernova_cg_alpha | CI10: addExtraMod("ty2"); | CK10: =MID(CI10,14,FIND(")",CI10,14)-14-1) -> ty2 | CM10: addExtraMod("uhnoise"); | CO10: =MID(CM10,14,FIND(")",CM10,14)-14-1) -> uhnoise | CQ10: addExtraMod("aberamp"); | CS10: =MID(CQ10,14,FIND(")",CQ10,14)-14-1) -> aberamp
B11: addExtraMod("cover2"); | D11: =MID(B11,14,FIND(")",B11,14)-14-1) -> cover2 | G11: addExtraMod("abberationyamp"); | I11: =MID(G11,14,FIND(")",G11,14)-14-1) -> abberationyamp | K11: addExtraMod("noteoverlayalp"); | M11: =MID(K11,14,FIND(")",K11,14)-14-1) -> noteoverlayalp | O11: addExtraMod("uialpha"); | Q11: =MID(O11,14,FIND(")",O11,14)-14-1) -> uialpha | S11: addExtraMod("glitchoffset"); | U11: =MID(S11,14,FIND(")",S11,14)-14-1) -> glitchoffset | W11: addExtraMod("hdistort"); | Y11: =MID(W11,14,FIND(")",W11,14)-14-1) -> hdistort | AA11: addExtraMod("posx"); | AC11: =MID(AA11,14,FIND(")",AA11,14)-14-1) -> posx | AE11: addExtraMod("hdistort"); | AG11: =MID(AE11,14,FIND(")",AE11,14)-14-1) -> hdistort | AI11: addExtraMod("lwtext"); | AK11: =MID(AI11,14,FIND(")",AI11,14)-14-1) -> lwtext | AM11: addExtraMod("glitchoffset"); | AO11: =MID(AM11,14,FIND(")",AM11,14)-14-1) -> glitchoffset | AQ11: addExtraMod("sinp"); | AS11: =MID(AQ11,14,FIND(")",AQ11,14)-14-1) -> sinp | AU11: addExtraMod("glitchoffset"); | AW11: =MID(AU11,14,FIND(")",AU11,14)-14-1) -> glitchoffset | AY11: addExtraMod("abberationyamp"); | BA11: =MID(AY11,14,FIND(")",AY11,14)-14-1) -> abberationyamp | BC11: addExtraMod("1_glitch"); | BE11: =MID(BC11,14,FIND(")",BC11,14)-14-1) -> 1_glitch | BG11: addExtraMod("glitchoffset"); | BI11: =MID(BG11,14,FIND(")",BG11,14)-14-1) -> glitchoffset | BK11: addExtraMod("cover2"); | BM11: =MID(BK11,14,FIND(")",BK11,14)-14-1) -> cover2 | BO11: addExtraMod("noteoverlayalp"); | BQ11: =MID(BO11,14,FIND(")",BO11,14)-14-1) -> noteoverlayalp | BS11: addExtraMod("abberationxamp"); | BU11: =MID(BS11,14,FIND(")",BS11,14)-14-1) -> abberationxamp | BW11: addExtraMod("uialpha"); | BY11: =MID(BW11,14,FIND(")",BW11,14)-14-1) -> uialpha | CA11: addExtraMod("abberationxamp"); | CC11: =MID(CA11,14,FIND(")",CA11,14)-14-1) -> abberationxamp | CE11: addExtraMod("glitchoffset"); | CG11: =MID(CE11,14,FIND(")",CE11,14)-14-1) -> glitchoffset | CI11: addExtraMod("ty3"); | CK11: =MID(CI11,14,FIND(")",CI11,14)-14-1) -> ty3 | CM11: addExtraMod("abberationxamp"); | CO11: =MID(CM11,14,FIND(")",CM11,14)-14-1) -> abberationxamp | CQ11: addExtraMod("uialpha"); | CS11: =MID(CQ11,14,FIND(")",CQ11,14)-14-1) -> uialpha
B12: addExtraMod("cover3"); | D12: =MID(B12,14,FIND(")",B12,14)-14-1) -> cover3 | G12: addExtraMod("fish"); | I12: =MID(G12,14,FIND(")",G12,14)-14-1) -> fish | K12: addExtraMod("shadermode"); | M12: =MID(K12,14,FIND(")",K12,14)-14-1) -> shadermode | O12: addExtraMod("cover1"); | Q12: =MID(O12,14,FIND(")",O12,14)-14-1) -> cover1 | S12: addExtraMod("uhnoise"); | U12: =MID(S12,14,FIND(")",S12,14)-14-1) -> uhnoise | W12: addExtraMod("fish"); | Y12: =MID(W12,14,FIND(")",W12,14)-14-1) -> fish | AA12: addExtraMod("posy"); | AC12: =MID(AA12,14,FIND(")",AA12,14)-14-1) -> posy | AE12: addExtraMod("fish"); | AG12: =MID(AE12,14,FIND(")",AE12,14)-14-1) -> fish | AM12: addExtraMod("uhnoise"); | AO12: =MID(AM12,14,FIND(")",AM12,14)-14-1) -> uhnoise | AQ12: addExtraMod("sino"); | AS12: =MID(AQ12,14,FIND(")",AQ12,14)-14-1) -> sino | AU12: addExtraMod("uhnoise"); | AW12: =MID(AU12,14,FIND(")",AU12,14)-14-1) -> uhnoise | AY12: addExtraMod("fish"); | BA12: =MID(AY12,14,FIND(")",AY12,14)-14-1) -> fish | BC12: addExtraMod("2_boost"); | BE12: =MID(BC12,14,FIND(")",BC12,14)-14-1) -> 2_boost | BG12: addExtraMod("uhnoise"); | BI12: =MID(BG12,14,FIND(")",BG12,14)-14-1) -> uhnoise | BK12: addExtraMod("cover3"); | BM12: =MID(BK12,14,FIND(")",BK12,14)-14-1) -> cover3 | BO12: addExtraMod("shadermode"); | BQ12: =MID(BO12,14,FIND(")",BO12,14)-14-1) -> shadermode | BS12: addExtraMod("abberationyamp"); | BU12: =MID(BS12,14,FIND(")",BS12,14)-14-1) -> abberationyamp | BW12: addExtraMod("cover1"); | BY12: =MID(BW12,14,FIND(")",BW12,14)-14-1) -> cover1 | CA12: addExtraMod("abberationyamp"); | CC12: =MID(CA12,14,FIND(")",CA12,14)-14-1) -> abberationyamp | CE12: addExtraMod("uhnoise"); | CG12: =MID(CE12,14,FIND(")",CE12,14)-14-1) -> uhnoise | CI12: addExtraMod("tyj"); | CK12: =MID(CI12,14,FIND(")",CI12,14)-14-1) -> tyj | CM12: addExtraMod("abberationyamp"); | CO12: =MID(CM12,14,FIND(")",CM12,14)-14-1) -> abberationyamp | CQ12: addExtraMod("cover1"); | CS12: =MID(CQ12,14,FIND(")",CQ12,14)-14-1) -> cover1
B13: addExtraMod("sina"); | D13: =MID(B13,14,FIND(")",B13,14)-14-1) -> sina | G13: addExtraMod("static"); | I13: =MID(G13,14,FIND(")",G13,14)-14-1) -> static | K13: addExtraMod("scorealph"); | M13: =MID(K13,14,FIND(")",K13,14)-14-1) -> scorealph | O13: addExtraMod("cover2"); | Q13: =MID(O13,14,FIND(")",O13,14)-14-1) -> cover2 | S13: addExtraMod("abberationxamp"); | U13: =MID(S13,14,FIND(")",S13,14)-14-1) -> abberationxamp | W13: addExtraMod("vig"); | Y13: =MID(W13,14,FIND(")",W13,14)-14-1) -> vig | AE13: addExtraMod("vig"); | AG13: =MID(AE13,14,FIND(")",AE13,14)-14-1) -> vig | AM13: addExtraMod("abberationxamp"); | AO13: =MID(AM13,14,FIND(")",AM13,14)-14-1) -> abberationxamp | AQ13: addExtraMod("cosa"); | AS13: =MID(AQ13,14,FIND(")",AQ13,14)-14-1) -> cosa | AU13: addExtraMod("abberationxamp"); | AW13: =MID(AU13,14,FIND(")",AU13,14)-14-1) -> abberationxamp | AY13: addExtraMod("static"); | BA13: =MID(AY13,14,FIND(")",AY13,14)-14-1) -> static | BC13: addExtraMod("2_dialbox_size"); | BE13: =MID(BC13,14,FIND(")",BC13,14)-14-1) -> 2_dialbox_size | BG13: addExtraMod("abberationxamp"); | BI13: =MID(BG13,14,FIND(")",BG13,14)-14-1) -> abberationxamp | BK13: addExtraMod("sina"); | BM13: =MID(BK13,14,FIND(")",BK13,14)-14-1) -> sina | BO13: addExtraMod("scorealph"); | BQ13: =MID(BO13,14,FIND(")",BO13,14)-14-1) -> scorealph | BS13: addExtraMod("fish"); | BU13: =MID(BS13,14,FIND(")",BS13,14)-14-1) -> fish | BW13: addExtraMod("cover2"); | BY13: =MID(BW13,14,FIND(")",BW13,14)-14-1) -> cover2 | CA13: addExtraMod("fish"); | CC13: =MID(CA13,14,FIND(")",CA13,14)-14-1) -> fish | CE13: addExtraMod("abberationxamp"); | CG13: =MID(CE13,14,FIND(")",CE13,14)-14-1) -> abberationxamp | CI13: addExtraMod("trz"); | CK13: =MID(CI13,14,FIND(")",CI13,14)-14-1) -> trz | CM13: addExtraMod("fish"); | CO13: =MID(CM13,14,FIND(")",CM13,14)-14-1) -> fish | CQ13: addExtraMod("cover2"); | CS13: =MID(CQ13,14,FIND(")",CQ13,14)-14-1) -> cover2
B14: addExtraMod("sinp"); | D14: =MID(B14,14,FIND(")",B14,14)-14-1) -> sinp | G14: addExtraMod("sg_endblip_destroy"); | I14: =MID(G14,14,FIND(")",G14,14)-14-1) -> sg_endblip_destroy | K14: addExtraMod("bgalph"); | M14: =MID(K14,14,FIND(")",K14,14)-14-1) -> bgalph | O14: addExtraMod("cover3"); | Q14: =MID(O14,14,FIND(")",O14,14)-14-1) -> cover3 | S14: addExtraMod("abberationyamp"); | U14: =MID(S14,14,FIND(")",S14,14)-14-1) -> abberationyamp | W14: addExtraMod("abx"); | Y14: =MID(W14,14,FIND(")",W14,14)-14-1) -> abx | AE14: addExtraMod("abx"); | AG14: =MID(AE14,14,FIND(")",AE14,14)-14-1) -> abx | AM14: addExtraMod("abberationyamp"); | AO14: =MID(AM14,14,FIND(")",AM14,14)-14-1) -> abberationyamp | AQ14: addExtraMod("cosp"); | AS14: =MID(AQ14,14,FIND(")",AQ14,14)-14-1) -> cosp | AU14: addExtraMod("abberationyamp"); | AW14: =MID(AU14,14,FIND(")",AU14,14)-14-1) -> abberationyamp | AY14: addExtraMod("sg_endblip_destroy"); | BA14: =MID(AY14,14,FIND(")",AY14,14)-14-1) -> sg_endblip_destroy | BC14: addExtraMod("2_dialbox_circles"); | BE14: =MID(BC14,14,FIND(")",BC14,14)-14-1) -> 2_dialbox_circles | BG14: addExtraMod("abberationyamp"); | BI14: =MID(BG14,14,FIND(")",BG14,14)-14-1) -> abberationyamp | BK14: addExtraMod("sinp"); | BM14: =MID(BK14,14,FIND(")",BK14,14)-14-1) -> sinp | BO14: addExtraMod("bgalph"); | BQ14: =MID(BO14,14,FIND(")",BO14,14)-14-1) -> bgalph | BS14: addExtraMod("static"); | BU14: =MID(BS14,14,FIND(")",BS14,14)-14-1) -> static | BW14: addExtraMod("cover3"); | BY14: =MID(BW14,14,FIND(")",BW14,14)-14-1) -> cover3 | CA14: addExtraMod("static"); | CC14: =MID(CA14,14,FIND(")",CA14,14)-14-1) -> static | CE14: addExtraMod("abberationyamp"); | CG14: =MID(CE14,14,FIND(")",CE14,14)-14-1) -> abberationyamp | CI14: addExtraMod("trz2"); | CK14: =MID(CI14,14,FIND(")",CI14,14)-14-1) -> trz2 | CM14: addExtraMod("static"); | CO14: =MID(CM14,14,FIND(")",CM14,14)-14-1) -> static | CQ14: addExtraMod("cover3"); | CS14: =MID(CQ14,14,FIND(")",CQ14,14)-14-1) -> cover3
B15: addExtraMod("sino"); | D15: =MID(B15,14,FIND(")",B15,14)-14-1) -> sino | G15: addExtraMod("sn_bg_alpha"); | I15: =MID(G15,14,FIND(")",G15,14)-14-1) -> sn_bg_alpha | K15: addExtraMod("gray"); | M15: =MID(K15,14,FIND(")",K15,14)-14-1) -> gray | O15: addExtraMod("wflash"); | Q15: =MID(O15,14,FIND(")",O15,14)-14-1) -> wflash | S15: addExtraMod("fish"); | U15: =MID(S15,14,FIND(")",S15,14)-14-1) -> fish | W15: addExtraMod("aby"); | Y15: =MID(W15,14,FIND(")",W15,14)-14-1) -> aby | AE15: addExtraMod("aby"); | AG15: =MID(AE15,14,FIND(")",AE15,14)-14-1) -> aby | AM15: addExtraMod("fish"); | AO15: =MID(AM15,14,FIND(")",AM15,14)-14-1) -> fish | AQ15: addExtraMod("coso"); | AS15: =MID(AQ15,14,FIND(")",AQ15,14)-14-1) -> coso | AU15: addExtraMod("fish"); | AW15: =MID(AU15,14,FIND(")",AU15,14)-14-1) -> fish | AY15: addExtraMod("sn_bg_alpha"); | BA15: =MID(AY15,14,FIND(")",AY15,14)-14-1) -> sn_bg_alpha | BC15: addExtraMod("2_bg_pics"); | BE15: =MID(BC15,14,FIND(")",BC15,14)-14-1) -> 2_bg_pics | BG15: addExtraMod("fish"); | BI15: =MID(BG15,14,FIND(")",BG15,14)-14-1) -> fish | BK15: addExtraMod("sino"); | BM15: =MID(BK15,14,FIND(")",BK15,14)-14-1) -> sino | BO15: addExtraMod("gray"); | BQ15: =MID(BO15,14,FIND(")",BO15,14)-14-1) -> gray | BS15: addExtraMod("sg_endblip_destroy"); | BU15: =MID(BS15,14,FIND(")",BS15,14)-14-1) -> sg_endblip_destroy | BW15: addExtraMod("wflash"); | BY15: =MID(BW15,14,FIND(")",BW15,14)-14-1) -> wflash | CA15: addExtraMod("sg_endblip_destroy"); | CC15: =MID(CA15,14,FIND(")",CA15,14)-14-1) -> sg_endblip_destroy | CE15: addExtraMod("fish"); | CG15: =MID(CE15,14,FIND(")",CE15,14)-14-1) -> fish | CI15: addExtraMod("tz"); | CK15: =MID(CI15,14,FIND(")",CI15,14)-14-1) -> tz | CM15: addExtraMod("sg_endblip_destroy"); | CO15: =MID(CM15,14,FIND(")",CM15,14)-14-1) -> sg_endblip_destroy | CQ15: addExtraMod("wflash"); | CS15: =MID(CQ15,14,FIND(")",CQ15,14)-14-1) -> wflash
B16: addExtraMod("cosa"); | D16: =MID(B16,14,FIND(")",B16,14)-14-1) -> cosa | G16: addExtraMod("sn_bg_fxamp"); | I16: =MID(G16,14,FIND(")",G16,14)-14-1) -> sn_bg_fxamp | K16: addExtraMod("barrel"); | M16: =MID(K16,14,FIND(")",K16,14)-14-1) -> barrel | O16: addExtraMod("rainbow"); | Q16: =MID(O16,14,FIND(")",O16,14)-14-1) -> rainbow | S16: addExtraMod("static"); | U16: =MID(S16,14,FIND(")",S16,14)-14-1) -> static | W16: addExtraMod("aberamp"); | Y16: =MID(W16,14,FIND(")",W16,14)-14-1) -> aberamp | AE16: addExtraMod("aberamp"); | AG16: =MID(AE16,14,FIND(")",AE16,14)-14-1) -> aberamp | AM16: addExtraMod("static"); | AO16: =MID(AM16,14,FIND(")",AM16,14)-14-1) -> static | AQ16: addExtraMod("tana"); | AS16: =MID(AQ16,14,FIND(")",AQ16,14)-14-1) -> tana | AU16: addExtraMod("static"); | AW16: =MID(AU16,14,FIND(")",AU16,14)-14-1) -> static | AY16: addExtraMod("sn_bg_fxamp"); | BA16: =MID(AY16,14,FIND(")",AY16,14)-14-1) -> sn_bg_fxamp | BC16: addExtraMod("2_dialbox_pulsar"); | BE16: =MID(BC16,14,FIND(")",BC16,14)-14-1) -> 2_dialbox_pulsar | BG16: addExtraMod("static"); | BI16: =MID(BG16,14,FIND(")",BG16,14)-14-1) -> static | BK16: addExtraMod("cosa"); | BM16: =MID(BK16,14,FIND(")",BK16,14)-14-1) -> cosa | BO16: addExtraMod("barrel"); | BQ16: =MID(BO16,14,FIND(")",BO16,14)-14-1) -> barrel | BS16: addExtraMod("sn_bg_alpha"); | BU16: =MID(BS16,14,FIND(")",BS16,14)-14-1) -> sn_bg_alpha | BW16: addExtraMod("rainbow"); | BY16: =MID(BW16,14,FIND(")",BW16,14)-14-1) -> rainbow | CA16: addExtraMod("sn_bg_alpha"); | CC16: =MID(CA16,14,FIND(")",CA16,14)-14-1) -> sn_bg_alpha | CE16: addExtraMod("static"); | CG16: =MID(CE16,14,FIND(")",CE16,14)-14-1) -> static | CI16: addExtraMod("tzx"); | CK16: =MID(CI16,14,FIND(")",CI16,14)-14-1) -> tzx | CM16: addExtraMod("sn_bg_alpha"); | CO16: =MID(CM16,14,FIND(")",CM16,14)-14-1) -> sn_bg_alpha | CQ16: addExtraMod("rainbow"); | CS16: =MID(CQ16,14,FIND(")",CQ16,14)-14-1) -> rainbow
B17: addExtraMod("cosp"); | D17: =MID(B17,14,FIND(")",B17,14)-14-1) -> cosp | G17: addExtraMod("sn_bg_animspd"); | I17: =MID(G17,14,FIND(")",G17,14)-14-1) -> sn_bg_animspd | K17: addExtraMod("barrel2"); | M17: =MID(K17,14,FIND(")",K17,14)-14-1) -> barrel2 | O17: addExtraMod("sides"); | Q17: =MID(O17,14,FIND(")",O17,14)-14-1) -> sides | S17: addExtraMod("supernova_cg_frame"); | U17: =MID(S17,14,FIND(")",S17,14)-14-1) -> supernova_cg_frame | W17: addExtraMod("uialpha"); | Y17: =MID(W17,14,FIND(")",W17,14)-14-1) -> uialpha | AE17: addExtraMod("uialpha"); | AG17: =MID(AE17,14,FIND(")",AE17,14)-14-1) -> uialpha | AM17: addExtraMod("supernova_cg_frame"); | AO17: =MID(AM17,14,FIND(")",AM17,14)-14-1) -> supernova_cg_frame | AQ17: addExtraMod("tanp"); | AS17: =MID(AQ17,14,FIND(")",AQ17,14)-14-1) -> tanp | AU17: addExtraMod("supernova_cg_frame"); | AW17: =MID(AU17,14,FIND(")",AU17,14)-14-1) -> supernova_cg_frame | AY17: addExtraMod("sn_bg_animspd"); | BA17: =MID(AY17,14,FIND(")",AY17,14)-14-1) -> sn_bg_animspd | BC17: addExtraMod("2_dialbox_speech"); | BE17: =MID(BC17,14,FIND(")",BC17,14)-14-1) -> 2_dialbox_speech | BG17: addExtraMod("supernova_cg_frame"); | BI17: =MID(BG17,14,FIND(")",BG17,14)-14-1) -> supernova_cg_frame | BK17: addExtraMod("cosp"); | BM17: =MID(BK17,14,FIND(")",BK17,14)-14-1) -> cosp | BO17: addExtraMod("barrel2"); | BQ17: =MID(BO17,14,FIND(")",BO17,14)-14-1) -> barrel2 | BS17: addExtraMod("sn_bg_fxamp"); | BU17: =MID(BS17,14,FIND(")",BS17,14)-14-1) -> sn_bg_fxamp | BW17: addExtraMod("sides"); | BY17: =MID(BW17,14,FIND(")",BW17,14)-14-1) -> sides | CA17: addExtraMod("sn_bg_fxamp"); | CC17: =MID(CA17,14,FIND(")",CA17,14)-14-1) -> sn_bg_fxamp | CE17: addExtraMod("supernova_cg_frame"); | CG17: =MID(CE17,14,FIND(")",CE17,14)-14-1) -> supernova_cg_frame | CI17: addExtraMod("tzy"); | CK17: =MID(CI17,14,FIND(")",CI17,14)-14-1) -> tzy | CM17: addExtraMod("sn_bg_fxamp"); | CO17: =MID(CM17,14,FIND(")",CM17,14)-14-1) -> sn_bg_fxamp | CQ17: addExtraMod("sides"); | CS17: =MID(CQ17,14,FIND(")",CQ17,14)-14-1) -> sides
B18: addExtraMod("coso"); | D18: =MID(B18,14,FIND(")",B18,14)-14-1) -> coso | G18: addExtraMod("yoffset"); | I18: =MID(G18,14,FIND(")",G18,14)-14-1) -> yoffset | K18: addExtraMod("hdistort"); | M18: =MID(K18,14,FIND(")",K18,14)-14-1) -> hdistort | O18: addExtraMod("notealp"); | Q18: =MID(O18,14,FIND(")",O18,14)-14-1) -> notealp | S18: addExtraMod("sg_endblip_destroy"); | U18: =MID(S18,14,FIND(")",S18,14)-14-1) -> sg_endblip_destroy | W18: addExtraMod("cover1"); | Y18: =MID(W18,14,FIND(")",W18,14)-14-1) -> cover1 | AE18: addExtraMod("cover1"); | AG18: =MID(AE18,14,FIND(")",AE18,14)-14-1) -> cover1 | AM18: addExtraMod("sg_endblip_destroy"); | AO18: =MID(AM18,14,FIND(")",AM18,14)-14-1) -> sg_endblip_destroy | AQ18: addExtraMod("tano"); | AS18: =MID(AQ18,14,FIND(")",AQ18,14)-14-1) -> tano | AU18: addExtraMod("sg_endblip_destroy"); | AW18: =MID(AU18,14,FIND(")",AU18,14)-14-1) -> sg_endblip_destroy | AY18: addExtraMod("yoffset"); | BA18: =MID(AY18,14,FIND(")",AY18,14)-14-1) -> yoffset | BC18: addExtraMod("2_bg_pinkbg_vis"); | BE18: =MID(BC18,14,FIND(")",BC18,14)-14-1) -> 2_bg_pinkbg_vis | BG18: addExtraMod("sg_endblip_destroy"); | BI18: =MID(BG18,14,FIND(")",BG18,14)-14-1) -> sg_endblip_destroy | BK18: addExtraMod("coso"); | BM18: =MID(BK18,14,FIND(")",BK18,14)-14-1) -> coso | BO18: addExtraMod("hdistort"); | BQ18: =MID(BO18,14,FIND(")",BO18,14)-14-1) -> hdistort | BS18: addExtraMod("sn_bg_animspd"); | BU18: =MID(BS18,14,FIND(")",BS18,14)-14-1) -> sn_bg_animspd | BW18: addExtraMod("notealp"); | BY18: =MID(BW18,14,FIND(")",BW18,14)-14-1) -> notealp | CA18: addExtraMod("sn_bg_animspd"); | CC18: =MID(CA18,14,FIND(")",CA18,14)-14-1) -> sn_bg_animspd | CE18: addExtraMod("sg_endblip_destroy"); | CG18: =MID(CE18,14,FIND(")",CE18,14)-14-1) -> sg_endblip_destroy | CI18: addExtraMod("tspl"); | CK18: =MID(CI18,14,FIND(")",CI18,14)-14-1) -> tspl | CM18: addExtraMod("sn_bg_animspd"); | CO18: =MID(CM18,14,FIND(")",CM18,14)-14-1) -> sn_bg_animspd | CQ18: addExtraMod("notealp"); | CS18: =MID(CQ18,14,FIND(")",CQ18,14)-14-1) -> notealp
B19: addExtraMod("tana"); | D19: =MID(B19,14,FIND(")",B19,14)-14-1) -> tana | K19: addExtraMod("fish"); | M19: =MID(K19,14,FIND(")",K19,14)-14-1) -> fish | O19: addExtraMod("video"); | Q19: =MID(O19,14,FIND(")",O19,14)-14-1) -> video | S19: addExtraMod("sn_bg_alpha"); | U19: =MID(S19,14,FIND(")",S19,14)-14-1) -> sn_bg_alpha | W19: addExtraMod("cover2"); | Y19: =MID(W19,14,FIND(")",W19,14)-14-1) -> cover2 | AE19: addExtraMod("cover2"); | AG19: =MID(AE19,14,FIND(")",AE19,14)-14-1) -> cover2 | AM19: addExtraMod("sn_bg_alpha"); | AO19: =MID(AM19,14,FIND(")",AM19,14)-14-1) -> sn_bg_alpha | AQ19: addExtraMod("static"); | AS19: =MID(AQ19,14,FIND(")",AQ19,14)-14-1) -> static | AU19: addExtraMod("sn_bg_alpha"); | AW19: =MID(AU19,14,FIND(")",AU19,14)-14-1) -> sn_bg_alpha | AY19: addExtraMod("dialogue_size"); | BA19: =MID(AY19,14,FIND(")",AY19,14)-14-1) -> dialogue_size | BC19: addExtraMod("3_pinkbg_alph"); | BE19: =MID(BC19,14,FIND(")",BC19,14)-14-1) -> 3_pinkbg_alph | BG19: addExtraMod("sn_bg_alpha"); | BI19: =MID(BG19,14,FIND(")",BG19,14)-14-1) -> sn_bg_alpha | BK19: addExtraMod("tana"); | BM19: =MID(BK19,14,FIND(")",BK19,14)-14-1) -> tana | BO19: addExtraMod("fish"); | BQ19: =MID(BO19,14,FIND(")",BO19,14)-14-1) -> fish | BS19: addExtraMod("yoffset"); | BU19: =MID(BS19,14,FIND(")",BS19,14)-14-1) -> yoffset | BW19: addExtraMod("video"); | BY19: =MID(BW19,14,FIND(")",BW19,14)-14-1) -> video | CA19: addExtraMod("yoffset"); | CC19: =MID(CA19,14,FIND(")",CA19,14)-14-1) -> yoffset | CE19: addExtraMod("sn_bg_alpha"); | CG19: =MID(CE19,14,FIND(")",CE19,14)-14-1) -> sn_bg_alpha | CI19: addExtraMod("sepx"); | CK19: =MID(CI19,14,FIND(")",CI19,14)-14-1) -> sepx | CM19: addExtraMod("yoffset"); | CO19: =MID(CM19,14,FIND(")",CM19,14)-14-1) -> yoffset | CQ19: addExtraMod("video"); | CS19: =MID(CQ19,14,FIND(")",CQ19,14)-14-1) -> video
B20: addExtraMod("tanp"); | D20: =MID(B20,14,FIND(")",B20,14)-14-1) -> tanp | K20: addExtraMod("vig"); | M20: =MID(K20,14,FIND(")",K20,14)-14-1) -> vig | O20: addExtraMod("noteoverlayalp"); | Q20: =MID(O20,14,FIND(")",O20,14)-14-1) -> noteoverlayalp | S20: addExtraMod("sn_bg2_alpha"); | U20: =MID(S20,14,FIND(")",S20,14)-14-1) -> sn_bg2_alpha | W20: addExtraMod("cover3"); | Y20: =MID(W20,14,FIND(")",W20,14)-14-1) -> cover3 | AE20: addExtraMod("cover3"); | AG20: =MID(AE20,14,FIND(")",AE20,14)-14-1) -> cover3 | AM20: addExtraMod("sn_bg_fxamp"); | AO20: =MID(AM20,14,FIND(")",AM20,14)-14-1) -> sn_bg_fxamp | AQ20: addExtraMod("vibx"); | AS20: =MID(AQ20,14,FIND(")",AQ20,14)-14-1) -> vibx | AU20: addExtraMod("sn_bg_fxamp"); | AW20: =MID(AU20,14,FIND(")",AU20,14)-14-1) -> sn_bg_fxamp | AY20: addExtraMod("text_alpha"); | BA20: =MID(AY20,14,FIND(")",AY20,14)-14-1) -> text_alpha | BC20: addExtraMod("3_noteblack"); | BE20: =MID(BC20,14,FIND(")",BC20,14)-14-1) -> 3_noteblack | BG20: addExtraMod("sn_bg_fxamp"); | BI20: =MID(BG20,14,FIND(")",BG20,14)-14-1) -> sn_bg_fxamp | BK20: addExtraMod("tanp"); | BM20: =MID(BK20,14,FIND(")",BK20,14)-14-1) -> tanp | BO20: addExtraMod("vig"); | BQ20: =MID(BO20,14,FIND(")",BO20,14)-14-1) -> vig | BS20: addExtraMod("scrollind0"); | BU20: =MID(BS20,14,FIND(")",BS20,14)-14-1) -> scrollind0 | BW20: addExtraMod("noteoverlayalp"); | BY20: =MID(BW20,14,FIND(")",BW20,14)-14-1) -> noteoverlayalp | CA20: addExtraMod("scrollind0"); | CC20: =MID(CA20,14,FIND(")",CA20,14)-14-1) -> scrollind0 | CE20: addExtraMod("sn_bg_fxamp"); | CG20: =MID(CE20,14,FIND(")",CE20,14)-14-1) -> sn_bg_fxamp | CI20: addExtraMod("sepy"); | CK20: =MID(CI20,14,FIND(")",CI20,14)-14-1) -> sepy | CM20: addExtraMod("tutorialX"); | CO20: =MID(CM20,14,FIND(")",CM20,14)-14-1) -> tutorialX | CQ20: addExtraMod("noteoverlayalp"); | CS20: =MID(CQ20,14,FIND(")",CQ20,14)-14-1) -> noteoverlayalp
B21: addExtraMod("tano"); | D21: =MID(B21,14,FIND(")",B21,14)-14-1) -> tano | K21: addExtraMod("abx"); | M21: =MID(K21,14,FIND(")",K21,14)-14-1) -> abx | O21: addExtraMod("astbars"); | Q21: =MID(O21,14,FIND(")",O21,14)-14-1) -> astbars | S21: addExtraMod("sn_bg_fxamp"); | U21: =MID(S21,14,FIND(")",S21,14)-14-1) -> sn_bg_fxamp | W21: addExtraMod("wflash"); | Y21: =MID(W21,14,FIND(")",W21,14)-14-1) -> wflash | AE21: addExtraMod("wflash"); | AG21: =MID(AE21,14,FIND(")",AE21,14)-14-1) -> wflash | AM21: addExtraMod("sn_bg_animspd"); | AO21: =MID(AM21,14,FIND(")",AM21,14)-14-1) -> sn_bg_animspd | AQ21: addExtraMod("viby"); | AS21: =MID(AQ21,14,FIND(")",AQ21,14)-14-1) -> viby | AU21: addExtraMod("sn_bg_animspd"); | AW21: =MID(AU21,14,FIND(")",AU21,14)-14-1) -> sn_bg_animspd | AY21: addExtraMod("dialogue_id"); | BA21: =MID(AY21,14,FIND(")",AY21,14)-14-1) -> dialogue_id | BC21: addExtraMod("4_plusbg_vis"); | BE21: =MID(BC21,14,FIND(")",BC21,14)-14-1) -> 4_plusbg_vis | BG21: addExtraMod("sn_bg_animspd"); | BI21: =MID(BG21,14,FIND(")",BG21,14)-14-1) -> sn_bg_animspd | BK21: addExtraMod("tano"); | BM21: =MID(BK21,14,FIND(")",BK21,14)-14-1) -> tano | BO21: addExtraMod("abx"); | BQ21: =MID(BO21,14,FIND(")",BO21,14)-14-1) -> abx | BS21: addExtraMod("scrollind1"); | BU21: =MID(BS21,14,FIND(")",BS21,14)-14-1) -> scrollind1 | BW21: addExtraMod("bgalph"); | BY21: =MID(BW21,14,FIND(")",BW21,14)-14-1) -> bgalph | CA21: addExtraMod("scrollind1"); | CC21: =MID(CA21,14,FIND(")",CA21,14)-14-1) -> scrollind1 | CE21: addExtraMod("sn_bg_animspd"); | CG21: =MID(CE21,14,FIND(")",CE21,14)-14-1) -> sn_bg_animspd | CI21: addExtraMod("spinang"); | CK21: =MID(CI21,14,FIND(")",CI21,14)-14-1) -> spinang | CM21: addExtraMod("tutorialA"); | CO21: =MID(CM21,14,FIND(")",CM21,14)-14-1) -> tutorialA
B22: addExtraMod("static"); | D22: =MID(B22,14,FIND(")",B22,14)-14-1) -> static | K22: addExtraMod("aby"); | M22: =MID(K22,14,FIND(")",K22,14)-14-1) -> aby | O22: addExtraMod("bgalph"); | Q22: =MID(O22,14,FIND(")",O22,14)-14-1) -> bgalph | S22: addExtraMod("sn_bg_animspd"); | U22: =MID(S22,14,FIND(")",S22,14)-14-1) -> sn_bg_animspd | W22: addExtraMod("rainbow"); | Y22: =MID(W22,14,FIND(")",W22,14)-14-1) -> rainbow | AE22: addExtraMod("rainbow"); | AG22: =MID(AE22,14,FIND(")",AE22,14)-14-1) -> rainbow | AM22: addExtraMod("setup_co"); | AO22: =MID(AM22,14,FIND(")",AM22,14)-14-1) -> setup_co | AQ22: addExtraMod("uialpha"); | AS22: =MID(AQ22,14,FIND(")",AQ22,14)-14-1) -> uialpha | AU22: addExtraMod("setup_co"); | AW22: =MID(AU22,14,FIND(")",AU22,14)-14-1) -> setup_co | AY22: addExtraMod("fruitmemoryx"); | BA22: =MID(AY22,14,FIND(")",AY22,14)-14-1) -> fruitmemoryx | BC22: addExtraMod("4_plusbg_pulse"); | BE22: =MID(BC22,14,FIND(")",BC22,14)-14-1) -> 4_plusbg_pulse | BG22: addExtraMod("setup_co"); | BI22: =MID(BG22,14,FIND(")",BG22,14)-14-1) -> setup_co | BK22: addExtraMod("static"); | BM22: =MID(BK22,14,FIND(")",BK22,14)-14-1) -> static | BO22: addExtraMod("aby"); | BQ22: =MID(BO22,14,FIND(")",BO22,14)-14-1) -> aby | BS22: addExtraMod("scrollind2"); | BU22: =MID(BS22,14,FIND(")",BS22,14)-14-1) -> scrollind2 | BW22: addExtraMod("holdoverlayalpha"); | BY22: =MID(BW22,14,FIND(")",BW22,14)-14-1) -> holdoverlayalpha | CA22: addExtraMod("scrollind2"); | CC22: =MID(CA22,14,FIND(")",CA22,14)-14-1) -> scrollind2 | CE22: addExtraMod("setup_co"); | CG22: =MID(CE22,14,FIND(")",CE22,14)-14-1) -> setup_co | CI22: addExtraMod("spinrad"); | CK22: =MID(CI22,14,FIND(")",CI22,14)-14-1) -> spinrad | CM22: addExtraMod("tutorialIndex"); | CO22: =MID(CM22,14,FIND(")",CM22,14)-14-1) -> tutorialIndex
B23: addExtraMod("uialpha"); | D23: =MID(B23,14,FIND(")",B23,14)-14-1) -> uialpha | K23: addExtraMod("aberamp"); | M23: =MID(K23,14,FIND(")",K23,14)-14-1) -> aberamp | O23: addExtraMod("fxdist1"); | Q23: =MID(O23,14,FIND(")",O23,14)-14-1) -> fxdist1 | S23: addExtraMod("setup_co"); | U23: =MID(S23,14,FIND(")",S23,14)-14-1) -> setup_co | W23: addExtraMod("sides"); | Y23: =MID(W23,14,FIND(")",W23,14)-14-1) -> sides | AE23: addExtraMod("sides"); | AG23: =MID(AE23,14,FIND(")",AE23,14)-14-1) -> sides | AQ23: addExtraMod("flicker"); | AS23: =MID(AQ23,14,FIND(")",AQ23,14)-14-1) -> flicker | AY23: addExtraMod("refreshdialogue"); | BA23: =MID(AY23,14,FIND(")",AY23,14)-14-1) -> refreshdialogue | BC23: addExtraMod("4_square_alph"); | BE23: =MID(BC23,14,FIND(")",BC23,14)-14-1) -> 4_square_alph | BG23: addExtraMod("setup_co_sect4"); | BI23: =MID(BG23,14,FIND(")",BG23,14)-14-1) -> setup_co_sect4 | BK23: addExtraMod("uialpha"); | BM23: =MID(BK23,14,FIND(")",BK23,14)-14-1) -> uialpha | BO23: addExtraMod("aberamp"); | BQ23: =MID(BO23,14,FIND(")",BO23,14)-14-1) -> aberamp | BS23: addExtraMod("scrollind3"); | BU23: =MID(BS23,14,FIND(")",BS23,14)-14-1) -> scrollind3 | BW23: addExtraMod("scorealph"); | BY23: =MID(BW23,14,FIND(")",BW23,14)-14-1) -> scorealph | CA23: addExtraMod("scrollind3"); | CC23: =MID(CA23,14,FIND(")",CA23,14)-14-1) -> scrollind3 | CE23: addExtraMod("setup_co_libertia"); | CG23: =MID(CE23,14,FIND(")",CE23,14)-14-1) -> setup_co_libertia | CI23: addExtraMod("siny"); | CK23: =MID(CI23,14,FIND(")",CI23,14)-14-1) -> siny
B24: addExtraMod("spinradiusx"); | D24: =MID(B24,14,FIND(")",B24,14)-14-1) -> spinradiusx | K24: addExtraMod("glitchamp"); | M24: =MID(K24,14,FIND(")",K24,14)-14-1) -> glitchamp | O24: addExtraMod("fxdist2"); | Q24: =MID(O24,14,FIND(")",O24,14)-14-1) -> fxdist2 | W24: addExtraMod("notealp"); | Y24: =MID(W24,14,FIND(")",W24,14)-14-1) -> notealp | AE24: addExtraMod("notealp"); | AG24: =MID(AE24,14,FIND(")",AE24,14)-14-1) -> notealp | AQ24: addExtraMod("twx1"); | AS24: =MID(AQ24,14,FIND(")",AQ24,14)-14-1) -> twx1 | BC24: addExtraMod("4_square_rotspd"); | BE24: =MID(BC24,14,FIND(")",BC24,14)-14-1) -> 4_square_rotspd | BG24: addExtraMod("setup_co_sect6"); | BI24: =MID(BG24,14,FIND(")",BG24,14)-14-1) -> setup_co_sect6 | BK24: addExtraMod("spinradiusx"); | BM24: =MID(BK24,14,FIND(")",BK24,14)-14-1) -> spinradiusx | BO24: addExtraMod("glitchamp"); | BQ24: =MID(BO24,14,FIND(")",BO24,14)-14-1) -> glitchamp | BS24: addExtraMod("scrollind4"); | BU24: =MID(BS24,14,FIND(")",BS24,14)-14-1) -> scrollind4 | BW24: addExtraMod("sg_lanelines0"); | BY24: =MID(BW24,14,FIND(")",BW24,14)-14-1) -> sg_lanelines0 | CA24: addExtraMod("scrollind4"); | CC24: =MID(CA24,14,FIND(")",CA24,14)-14-1) -> scrollind4 | CI24: addExtraMod("vib"); | CK24: =MID(CI24,14,FIND(")",CI24,14)-14-1) -> vib
B25: addExtraMod("spinradiusz"); | D25: =MID(B25,14,FIND(")",B25,14)-14-1) -> spinradiusz | K25: addExtraMod("glitchoffset"); | M25: =MID(K25,14,FIND(")",K25,14)-14-1) -> glitchoffset | O25: addExtraMod("parttimer"); | Q25: =MID(O25,14,FIND(")",O25,14)-14-1) -> parttimer | W25: addExtraMod("video"); | Y25: =MID(W25,14,FIND(")",W25,14)-14-1) -> video | AE25: addExtraMod("video"); | AG25: =MID(AE25,14,FIND(")",AE25,14)-14-1) -> video | AQ25: addExtraMod("twy1"); | AS25: =MID(AQ25,14,FIND(")",AQ25,14)-14-1) -> twy1 | BC25: addExtraMod("4_square_scale"); | BE25: =MID(BC25,14,FIND(")",BC25,14)-14-1) -> 4_square_scale | BG25: addExtraMod("setup_co_sect8"); | BI25: =MID(BG25,14,FIND(")",BG25,14)-14-1) -> setup_co_sect8 | BK25: addExtraMod("spinradiusz"); | BM25: =MID(BK25,14,FIND(")",BK25,14)-14-1) -> spinradiusz | BO25: addExtraMod("glitchoffset"); | BQ25: =MID(BO25,14,FIND(")",BO25,14)-14-1) -> glitchoffset | BS25: addExtraMod("scrollind5"); | BU25: =MID(BS25,14,FIND(")",BS25,14)-14-1) -> scrollind5 | BW25: addExtraMod("sg_lanelines1"); | BY25: =MID(BW25,14,FIND(")",BW25,14)-14-1) -> sg_lanelines1 | CA25: addExtraMod("scrollind5"); | CC25: =MID(CA25,14,FIND(")",CA25,14)-14-1) -> scrollind5 | CI25: addExtraMod("hid1") | CK25: =MID(CI25,14,FIND(")",CI25,14)-14-1) -> hid1
B26: addExtraMod("fakezy"); | D26: =MID(B26,14,FIND(")",B26,14)-14-1) -> fakezy | K26: addExtraMod("uhnoise"); | M26: =MID(K26,14,FIND(")",K26,14)-14-1) -> uhnoise | W26: addExtraMod("noteoverlayalp"); | Y26: =MID(W26,14,FIND(")",W26,14)-14-1) -> noteoverlayalp | AE26: addExtraMod("noteoverlayalp"); | AG26: =MID(AE26,14,FIND(")",AE26,14)-14-1) -> noteoverlayalp | AQ26: addExtraMod("twa1"); | AS26: =MID(AQ26,14,FIND(")",AQ26,14)-14-1) -> twa1 | BC26: addExtraMod("5_video_toggle"); | BE26: =MID(BC26,14,FIND(")",BC26,14)-14-1) -> 5_video_toggle | BG26: addExtraMod("setup_co_sect12"); | BI26: =MID(BG26,14,FIND(")",BG26,14)-14-1) -> setup_co_sect12 | BK26: addExtraMod("fakezy"); | BM26: =MID(BK26,14,FIND(")",BK26,14)-14-1) -> fakezy | BO26: addExtraMod("uhnoise"); | BQ26: =MID(BO26,14,FIND(")",BO26,14)-14-1) -> uhnoise | BS26: addExtraMod("scrollind6"); | BU26: =MID(BS26,14,FIND(")",BS26,14)-14-1) -> scrollind6 | BW26: addExtraMod("sg_lanelines2"); | BY26: =MID(BW26,14,FIND(")",BW26,14)-14-1) -> sg_lanelines2 | CA26: addExtraMod("scrollind6"); | CC26: =MID(CA26,14,FIND(")",CA26,14)-14-1) -> scrollind6 | CI26: addExtraMod("hid2") | CK26: =MID(CI26,14,FIND(")",CI26,14)-14-1) -> hid2
B27: addExtraMod("fakezyb"); | D27: =MID(B27,14,FIND(")",B27,14)-14-1) -> fakezyb | K27: addExtraMod("abberationxamp"); | M27: =MID(K27,14,FIND(")",K27,14)-14-1) -> abberationxamp | W27: addExtraMod("df_countdown"); | Y27: =MID(W27,14,FIND(")",W27,14)-14-1) -> df_countdown | AE27: addExtraMod("df_countdown"); | AG27: =MID(AE27,14,FIND(")",AE27,14)-14-1) -> df_countdown | AQ27: addExtraMod("twr1"); | AS27: =MID(AQ27,14,FIND(")",AQ27,14)-14-1) -> twr1 | BC27: addExtraMod("5_video_alph"); | BE27: =MID(BC27,14,FIND(")",BC27,14)-14-1) -> 5_video_alph | BG27: addExtraMod("setup_co_sect14"); | BI27: =MID(BG27,14,FIND(")",BG27,14)-14-1) -> setup_co_sect14 | BK27: addExtraMod("fakezyb"); | BM27: =MID(BK27,14,FIND(")",BK27,14)-14-1) -> fakezyb | BO27: addExtraMod("abberationxamp"); | BQ27: =MID(BO27,14,FIND(")",BO27,14)-14-1) -> abberationxamp | BS27: addExtraMod("stopmotionnoteskin"); | BU27: =MID(BS27,14,FIND(")",BS27,14)-14-1) -> stopmotionnoteskin | BW27: addExtraMod("sg_judgeline"); | BY27: =MID(BW27,14,FIND(")",BW27,14)-14-1) -> sg_judgeline | CA27: addExtraMod("stopmotionnoteskin"); | CC27: =MID(CA27,14,FIND(")",CA27,14)-14-1) -> stopmotionnoteskin | CI27: addExtraMod("hid3") | CK27: =MID(CI27,14,FIND(")",CI27,14)-14-1) -> hid3
B28: addExtraMod("float"); | D28: =MID(B28,14,FIND(")",B28,14)-14-1) -> float | K28: addExtraMod("abberationyamp"); | M28: =MID(K28,14,FIND(")",K28,14)-14-1) -> abberationyamp | W28: addExtraMod("lr_slash"); | Y28: =MID(W28,14,FIND(")",W28,14)-14-1) -> lr_slash | AE28: addExtraMod("lr_slash"); | AG28: =MID(AE28,14,FIND(")",AE28,14)-14-1) -> lr_slash | AQ28: addExtraMod("twx2"); | AS28: =MID(AQ28,14,FIND(")",AQ28,14)-14-1) -> twx2 | BC28: addExtraMod("5_bord_alph"); | BE28: =MID(BC28,14,FIND(")",BC28,14)-14-1) -> 5_bord_alph | BG28: addExtraMod("setup_co_end"); | BI28: =MID(BG28,14,FIND(")",BG28,14)-14-1) -> setup_co_end | BK28: addExtraMod("float"); | BM28: =MID(BK28,14,FIND(")",BK28,14)-14-1) -> float | BO28: addExtraMod("abberationyamp"); | BQ28: =MID(BO28,14,FIND(")",BO28,14)-14-1) -> abberationyamp | BS28: addExtraMod("storycheck1"); | BU28: =MID(BS28,14,FIND(")",BS28,14)-14-1) -> storycheck1 | BW28: addExtraMod("sg_starspawner"); | BY28: =MID(BW28,14,FIND(")",BW28,14)-14-1) -> sg_starspawner | CA28: addExtraMod("storycheck1"); | CC28: =MID(CA28,14,FIND(")",CA28,14)-14-1) -> storycheck1 | CI28: addExtraMod("hid4") | CK28: =MID(CI28,14,FIND(")",CI28,14)-14-1) -> hid4
B29: addExtraMod("wiggly"); | D29: =MID(B29,14,FIND(")",B29,14)-14-1) -> wiggly | K29: addExtraMod("fish"); | M29: =MID(K29,14,FIND(")",K29,14)-14-1) -> fish | W29: addExtraMod("lr_slash_color"); | Y29: =MID(W29,14,FIND(")",W29,14)-14-1) -> lr_slash_color | AE29: addExtraMod("lr_slash_color"); | AG29: =MID(AE29,14,FIND(")",AE29,14)-14-1) -> lr_slash_color | AQ29: addExtraMod("twy2"); | AS29: =MID(AQ29,14,FIND(")",AQ29,14)-14-1) -> twy2 | BC29: addExtraMod("5_abber"); | BE29: =MID(BC29,14,FIND(")",BC29,14)-14-1) -> 5_abber | BG29: addExtraMod("plaudite_jacket"); | BI29: =MID(BG29,14,FIND(")",BG29,14)-14-1) -> plaudite_jacket | BK29: addExtraMod("wiggly"); | BM29: =MID(BK29,14,FIND(")",BK29,14)-14-1) -> wiggly | BO29: addExtraMod("fish"); | BQ29: =MID(BO29,14,FIND(")",BO29,14)-14-1) -> fish | BS29: addExtraMod("storycheck2"); | BU29: =MID(BS29,14,FIND(")",BS29,14)-14-1) -> storycheck2 | BW29: addExtraMod("starspd_low"); | BY29: =MID(BW29,14,FIND(")",BW29,14)-14-1) -> starspd_low | CA29: addExtraMod("storycheck2"); | CC29: =MID(CA29,14,FIND(")",CA29,14)-14-1) -> storycheck2 | CI29: addExtraMod("hid5") | CK29: =MID(CI29,14,FIND(")",CI29,14)-14-1) -> hid5
B30: addExtraMod("twx1"); | D30: =MID(B30,14,FIND(")",B30,14)-14-1) -> twx1 | K30: addExtraMod("static"); | M30: =MID(K30,14,FIND(")",K30,14)-14-1) -> static | W30: addExtraMod("lr_sides_blue"); | Y30: =MID(W30,14,FIND(")",W30,14)-14-1) -> lr_sides_blue | AE30: addExtraMod("lr_sides_blue"); | AG30: =MID(AE30,14,FIND(")",AE30,14)-14-1) -> lr_sides_blue | AQ30: addExtraMod("twa2"); | AS30: =MID(AQ30,14,FIND(")",AQ30,14)-14-1) -> twa2 | BC30: addExtraMod("6_glitch"); | BE30: =MID(BC30,14,FIND(")",BC30,14)-14-1) -> 6_glitch | BG30: addExtraMod("plaudite_sect2bg"); | BI30: =MID(BG30,14,FIND(")",BG30,14)-14-1) -> plaudite_sect2bg | BK30: addExtraMod("planea"); | BM30: =MID(BK30,14,FIND(")",BK30,14)-14-1) -> planea | BO30: addExtraMod("static"); | BQ30: =MID(BO30,14,FIND(")",BO30,14)-14-1) -> static | BS30: addExtraMod("sm_bg_enable"); | BU30: =MID(BS30,14,FIND(")",BS30,14)-14-1) -> sm_bg_enable | BW30: addExtraMod("starspd_high"); | BY30: =MID(BW30,14,FIND(")",BW30,14)-14-1) -> starspd_high | CA30: addExtraMod("sm_bg_enable"); | CC30: =MID(CA30,14,FIND(")",CA30,14)-14-1) -> sm_bg_enable
B31: addExtraMod("twy1"); | D31: =MID(B31,14,FIND(")",B31,14)-14-1) -> twy1 | K31: addExtraMod("fx_hue_hue"); | M31: =MID(K31,14,FIND(")",K31,14)-14-1) -> fx_hue_hue | W31: addExtraMod("lr_sides_red"); | Y31: =MID(W31,14,FIND(")",W31,14)-14-1) -> lr_sides_red | AE31: addExtraMod("lr_sides_red"); | AG31: =MID(AE31,14,FIND(")",AE31,14)-14-1) -> lr_sides_red | AQ31: addExtraMod("twr2"); | AS31: =MID(AQ31,14,FIND(")",AQ31,14)-14-1) -> twr2 | BC31: addExtraMod("6_video_toggle"); | BE31: =MID(BC31,14,FIND(")",BC31,14)-14-1) -> 6_video_toggle | BG31: addExtraMod("plaudite_sect5bg"); | BI31: =MID(BG31,14,FIND(")",BG31,14)-14-1) -> plaudite_sect5bg | BK31: addExtraMod("rotdir"); | BM31: =MID(BK31,14,FIND(")",BK31,14)-14-1) -> rotdir | BO31: addExtraMod("fx_hue_hue"); | BQ31: =MID(BO31,14,FIND(")",BO31,14)-14-1) -> fx_hue_hue | BS31: addExtraMod("sm_bg_fade_alpha"); | BU31: =MID(BS31,14,FIND(")",BS31,14)-14-1) -> sm_bg_fade_alpha | BW31: addExtraMod("star_pause"); | BY31: =MID(BW31,14,FIND(")",BW31,14)-14-1) -> star_pause | CA31: addExtraMod("sm_bg_fade_alpha"); | CC31: =MID(CA31,14,FIND(")",CA31,14)-14-1) -> sm_bg_fade_alpha
B32: addExtraMod("twa1"); | D32: =MID(B32,14,FIND(")",B32,14)-14-1) -> twa1 | K32: addExtraMod("fx_hue_saturation"); | M32: =MID(K32,14,FIND(")",K32,14)-14-1) -> fx_hue_saturation | W32: addExtraMod("lr_sides_rev_blue"); | Y32: =MID(W32,14,FIND(")",W32,14)-14-1) -> lr_sides_rev_blue | AE32: addExtraMod("lr_sides_rev_blue"); | AG32: =MID(AE32,14,FIND(")",AE32,14)-14-1) -> lr_sides_rev_blue | AQ32: addExtraMod("twx3"); | AS32: =MID(AQ32,14,FIND(")",AQ32,14)-14-1) -> twx3 | BC32: addExtraMod("6_video_alph"); | BE32: =MID(BC32,14,FIND(")",BC32,14)-14-1) -> 6_video_alph | BG32: addExtraMod("plaudite_sect7bg"); | BI32: =MID(BG32,14,FIND(")",BG32,14)-14-1) -> plaudite_sect7bg | BK32: addExtraMod("texta"); | BM32: =MID(BK32,14,FIND(")",BK32,14)-14-1) -> texta | BO32: addExtraMod("fx_hue_saturation"); | BQ32: =MID(BO32,14,FIND(")",BO32,14)-14-1) -> fx_hue_saturation | BS32: addExtraMod("temporaryshadercreate"); | BU32: =MID(BS32,14,FIND(")",BS32,14)-14-1) -> temporaryshadercreate | BW32: addExtraMod("starspawn"); | BY32: =MID(BW32,14,FIND(")",BW32,14)-14-1) -> starspawn | CA32: addExtraMod("temporaryshadercreate"); | CC32: =MID(CA32,14,FIND(")",CA32,14)-14-1) -> temporaryshadercreate
B33: addExtraMod("twr1"); | D33: =MID(B33,14,FIND(")",B33,14)-14-1) -> twr1 | K33: addExtraMod("fx_edge"); | M33: =MID(K33,14,FIND(")",K33,14)-14-1) -> fx_edge | W33: addExtraMod("lr_sides_rev_red"); | Y33: =MID(W33,14,FIND(")",W33,14)-14-1) -> lr_sides_rev_red | AE33: addExtraMod("lr_sides_rev_red"); | AG33: =MID(AE33,14,FIND(")",AE33,14)-14-1) -> lr_sides_rev_red | AQ33: addExtraMod("twy3"); | AS33: =MID(AQ33,14,FIND(")",AQ33,14)-14-1) -> twy3 | BC33: addExtraMod("6_red_layer_alph"); | BE33: =MID(BC33,14,FIND(")",BC33,14)-14-1) -> 6_red_layer_alph | BG33: addExtraMod("unraveling_sidething"); | BI33: =MID(BG33,14,FIND(")",BG33,14)-14-1) -> unraveling_sidething | BK33: addExtraMod("twx1"); | BM33: =MID(BK33,14,FIND(")",BK33,14)-14-1) -> twx1 | BO33: addExtraMod("fx_edge"); | BQ33: =MID(BO33,14,FIND(")",BO33,14)-14-1) -> fx_edge | BS33: addExtraMod("temporaryshaderdestroy"); | BU33: =MID(BS33,14,FIND(")",BS33,14)-14-1) -> temporaryshaderdestroy | BW33: addExtraMod("sg_endblip"); | BY33: =MID(BW33,14,FIND(")",BW33,14)-14-1) -> sg_endblip | CA33: addExtraMod("temporaryshaderdestroy"); | CC33: =MID(CA33,14,FIND(")",CA33,14)-14-1) -> temporaryshaderdestroy
B34: addExtraMod("twx2"); | D34: =MID(B34,14,FIND(")",B34,14)-14-1) -> twx2 | K34: addExtraMod("fx_posterize"); | M34: =MID(K34,14,FIND(")",K34,14)-14-1) -> fx_posterize | W34: addExtraMod("lr_mountain_bg"); | Y34: =MID(W34,14,FIND(")",W34,14)-14-1) -> lr_mountain_bg | AE34: addExtraMod("lr_mountain_bg"); | AG34: =MID(AE34,14,FIND(")",AE34,14)-14-1) -> lr_mountain_bg | AQ34: addExtraMod("twa3"); | AS34: =MID(AQ34,14,FIND(")",AQ34,14)-14-1) -> twa3 | BC34: addExtraMod("6_static_alph"); | BE34: =MID(BC34,14,FIND(")",BC34,14)-14-1) -> 6_static_alph | BG34: addExtraMod("astellion_sidething"); | BI34: =MID(BG34,14,FIND(")",BG34,14)-14-1) -> astellion_sidething | BK34: addExtraMod("twy1"); | BM34: =MID(BK34,14,FIND(")",BK34,14)-14-1) -> twy1 | BO34: addExtraMod("fx_posterize"); | BQ34: =MID(BO34,14,FIND(")",BO34,14)-14-1) -> fx_posterize | BS34: addExtraMod("sm_leftbg_frameset"); | BU34: =MID(BS34,14,FIND(")",BS34,14)-14-1) -> sm_leftbg_frameset | BW34: addExtraMod("sg_bg_alpha"); | BY34: =MID(BW34,14,FIND(")",BW34,14)-14-1) -> sg_bg_alpha | CA34: addExtraMod("sm_leftbg_frameset"); | CC34: =MID(CA34,14,FIND(")",CA34,14)-14-1) -> sm_leftbg_frameset
